# Running on vgne084
# Started at Wed Dec 4 12:10:38 CET 2019
# nice_mnist.py 
Using TensorFlow backend.
WARNING:tensorflow:From /idiap/user/dbaby/anaconda3/envs/tf/lib/python3.7/site-packages/tensorflow/python/ops/resource_variable_ops.py:435: colocate_with (from tensorflow.python.framework.ops) is deprecated and will be removed in a future version.
Instructions for updating:
Colocations handled automatically by placer.
Traceback (most recent call last):
  File "/idiap/user/dbaby/work/code005_nice/nice_mnist.py", line 156, in <module>
    nice.load_weights('nice3_nobnorm_mnist_gaussian_lr0.001_b2048_U0.01init_es.h5')
  File "/idiap/user/dbaby/anaconda3/envs/tf/lib/python3.7/site-packages/keras/engine/saving.py", line 492, in load_wrapper
    return load_function(*args, **kwargs)
  File "/idiap/user/dbaby/anaconda3/envs/tf/lib/python3.7/site-packages/keras/engine/network.py", line 1221, in load_weights
    with h5py.File(filepath, mode='r') as f:
  File "/idiap/user/dbaby/anaconda3/envs/tf/lib/python3.7/site-packages/h5py/_hl/files.py", line 394, in __init__
    swmr=swmr)
  File "/idiap/user/dbaby/anaconda3/envs/tf/lib/python3.7/site-packages/h5py/_hl/files.py", line 170, in make_fid
    fid = h5f.open(name, flags, fapl=fapl)
  File "h5py/_objects.pyx", line 54, in h5py._objects.with_phil.wrapper
  File "h5py/_objects.pyx", line 55, in h5py._objects.with_phil.wrapper
  File "h5py/h5f.pyx", line 85, in h5py.h5f.open
OSError: Unable to open file (unable to open file: name = 'nice3_nobnorm_mnist_gaussian_lr0.001_b2048_U0.01init_es.h5', errno = 2, error message = 'No such file or directory', flags = 0, o_flags = 0)
# Accounting: time=18 threads=1
# Finished at Wed Dec 4 12:10:56 CET 2019 with status 1
